Workbook

Sheet MOQ
A1: MRP BAUMON
A2: Qtd | B2: Produto | C2: Código Bemol | D2: DESCRIÇÃO | E2: MOQ Mínimo | F2: Produtos por caixa Master Box | G2: Quantidade de Caixa Master | H2: CBM por Caixa Master | I2: CBM Total
A3: 1 | C3: 238697 | D3: FRITAD BAUMON AIR FRYER 35L YJ-613D PT | E3: 1500 | F3: 2 | G3: =E3/F3 -> 750 | H3: 0.064 | I3: =H3*G3 -> 48
A4: 2 | C4: 238698 | D4: FRITAD BAUMON AIR FRYER 12L GSE021 PT | E4: 700 | F4: 1 | G4: =E4/F4 -> 700 | H4: 0.063 | I4: =H4*G4 -> 44.1
A5: 3 | C5: 238699 | D5: CAFETEIRA BAUMON 108TS PT/PR | E5: 1800 | F5: 4 | G5: =E5/F5 -> 450 | H5: 0.073 | I5: =H5*G5 -> 32.85
A6: 4 | C6: 238700 | D6: SANDUICHEIRA BAUMON FS-8009C PT | E6: 2004 | F6: 6 | G6: =E6/F6 -> 334 | H6: 0.041 | I6: =H6*G6 -> 13.694
A7: 5 | C7: 238721 | D7: GRILL BAUMON 9228D PT | E7: 2010 | F7: 6 | G7: =E7/F7 -> 335 | H7: 0.068 | I7: =H7*G7 -> 22.78
A8: 6 | C8: 238722 | D8: FERRO BAUMON SECO LM-209A AZ | E8: 2604 | F8: 12 | G8: =E8/F8 -> 217 | H8: 0.046 | I8: =H8*G8 -> 9.982
A9: 7 | C9: 238723 | D9: FERRO BAUMON VAPOR LM-2262 AZ | E9: 2450 | F9: 10 | G9: =E9/F9 -> 245 | H9: 0.046 | I9: =H9*G9 -> 11.27
A10: 8 | C10: 267869 | D10: POTE HERM BAUMON RET 400ML C/ TAMPA R145 | E10: 3024 | F10: 36 | G10: =E10/F10 -> 84 | H10: 0.04394971 | I10: =H10*G10 -> 3.6917756
A11: 9 | C11: 267870 | D11: POTE HERM BAUMON RET 630ML C/ TAMPA R170 | E11: 3000 | F11: 24 | G11: =E11/F11 -> 125 | H11: 0.04353888 | I11: =H11*G11 -> 5.44236
A12: 10 | C12: 267931 | D12: POTE HERM BAUMON 1410ML R220-2FULL | E12: 3000 | F12: 12 | G12: =E12/F12 -> 250 | H12: 0.04136 | I12: =H12*G12 -> 10.34
A13: 11 | C13: 267932 | D13: POTE HERM BAUMON 1040ML C/TAM R195-2FULL | E13: 3000 | F13: 24 | G13: =E13/F13 -> 125 | H13: 0.0623922 | I13: =H13*G13 -> 7.799025
A14: 12 | C14: 267936 | D14: POTE HERM BAUMON QD 750ML C/TAMP S150-2 | E14: 3000 | F14: 24 | G14: =E14/F14 -> 125 | H14: 0.04025334 | I14: =H14*G14 -> 5.0316675
... A55: 53 | C55: 370451 | D55: Sup p/TV Baumon Fixo LCD-800 PT | E55: 6000 | F55: 40 | G55: =E55/F55 -> 150 | H55: 0.0337 | I55: =H55*G55 -> 5.055
A56: 54 | D56: Sup p/TV Baumon Universal YN-LED001 PT | E56: 600 | F56: 20 | G56: =E56/F56 -> 30 | H56: 0.0125 | I56: =H56*G56 -> 0.375
A57: 55 | C57: 370452 | D57: Sup p/TV Baumon fixo YN-109MF PT | E57: 3000 | F57: 10 | G57: =E57/F57 -> 300 | H57: 0.0359 | I57: =H57*G57 -> 10.77
A58: 56 | C58: 370453 | D58: Sup p/TV Baumon Articulado YN-927AT PT | E58: 2760 | F58: 6 | G58: =E58/F58 -> 460 | H58: 0.0416 | I58: =H58*G58 -> 19.136
A59: 57 | D59: Jogo de Cama solteiro 100% penteado 180 fios azul | E59: 264 | F59: 12 | G59: =E59/F59 -> 22 | H59: 2.115564 | I59: =H59*G59 -> 46.542408
A60: 58 | D60: Jogo de Cama solteiro 100% penteado 180 fios bege | E60: 264 | F60: 12 | G60: =E60/F60 -> 22 | H60: 2.163645 | I60: =H60*G60 -> 47.60019
A61: 59 | D61: Jogo de Cama solteiro 100% penteado 180 fios verde | E61: 264 | F61: 12 | G61: =E61/F61 -> 22 | H61: 2.115564 | I61: =H61*G61 -> 46.542408
A62: 60 | D62: Jogo de cama casal 100% penteado 200 fios azul | E62: 264 | F62: 12 | G62: =E62/F62 -> 22 | H62: 4.12566 | I62: =H62*G62 -> 90.76452
A63: 61 | D63: Jogo de cama casal 100% penteado 200 fios bege | E63: 180 | F63: 12 | G63: =E63/F63 -> 15 | H63: 4.12566 | I63: =H63*G63 -> 61.8849
A64: 62 | D64: Jogo de cama casal 100% penteado 200 fios verde | E64: 264 | F64: 12 | G64: =E64/F64 -> 22 | H64: 4.12566 | I64: =H64*G64 -> 90.76452
A65: 63 | D65: Jogo de cama Queen 100% penteado 200 fios Azul | E65: 264 | F65: 10 | G65: =E65/F65 -> 26.4 | H65: 4.55994 | I65: =H65*G65 -> 120.38242
A66: 64 | D66: Jogo de cama Queen 100% penteado 200 fios bege | E66: 264 | F66: 10 | G66: =E66/F66 -> 26.4 | H66: 4.55994 | I66: =H66*G66 -> 120.38242
A67: 65 | D67: Jogo de cama Queen 100% penteado 200 fios verde | E67: 264 | F67: 10 | G67: =E67/F67 -> 26.4 | H67: 4.55994 | I67: =H67*G67 -> 120.38242
A68: 66 | D68: Jogo de cama King 100% penteado 200 fios Azul | E68: 264 | F68: 8 | G68: =E68/F68 -> 33 | H68: 2.877105 | I68: =H68*G68 -> 94.944465
A69: 67 | D69: Jogo de cama King 100% penteado 200 fios Bege | E69: 264 | F69: 8 | G69: =E69/F69 -> 33 | H69: 2.985675 | I69: =H69*G69 -> 98.527275
A70: 68 | D70: Jogo de cama King 100% penteado 200 fios Verde | E70: 264 | F70: 8 | G70: =E70/F70 -> 33 | H70: 2.877105 | I70: =H70*G70 -> 94.944465
... A79: 77 | D79: 2 toalhas + rosto 100% algodão (126cm x 68 cm) 500 GSM rosa | E79: 200 | F79: 8 | G79: =E79/F79 -> 25 | H79: 5.082 | I79: =H79*G79 -> 127.05

Sheet MRP NACIONAL
F1: Data do pedido
F2: Saída - ETD | G2: 46092 | H2: 46086 | I2: 46064 | J2: 46126 | N2: 46126 | P2: 46114 | X2: 46162
F3: Previsão de Chegada - ETA | G3: 46153 | H3: 05/05/026 | I3: 46142 | J3: 46187 | N3: 46187 | P3: 46191 | X3: 46219
A4: Qtd | B4: Categoria | C4: GM9 Descrição | D4: Trade | E4: Código | F4: Descrição | G4: Bemol 36 | H4: Bemol 37 | I4: Bemol 38 | J4: Bemol 39 | K4: Bemol 40 | L4: Bemol 41 | M4: Bemol 42 | N4: Bemol 43 | O4: Bemol 44 | P4: Bemol 45 | Q4: Bemol 46 | R4: Bemol 47 | S4: Bemol 48 | T4: Bemol 49 | U4: Bemol 50 | V4: Bemol 51 | W4: Bemol 52 | X4: Bemol 53 | Y4: Bemol 54 | Z4: Bemol 55 | AA4: Bemol 56 | AB4: Bemol 57 | AC4: Bemol 58 | AD4: Bemol 59 | AE4: Bemol 60 | AF4: Bemol 61 | AG4: Bemol 62 | AH4: Bemol 63 | AI4: Bemol 64 | AJ4: Bemol 65 | AK4: Bemol 66 | AL4: Bemol 67 | AM4: Bemol 68 | AN4: Bemol 69 | AO4: Bemol 70 | AP4: Bemol 71 | AQ4: Bemol 72 | AR4: Bemol 73 | AS4: Bemol 74
A5: 1 | B5: 111002004 | C5: VENTILADOR DE MESA | D5: Fresnomaq | E5: 252881 | F5: VENT MESA 50 BAUMON 2EM1 FW10595 PT | AL5: =SUM(G5:AJ5) -> 0
A6: 2 | B6: 111002003 | C6: VENTILADOR DE COLUNA | D6: Importad | E6: 252882 | F6: VENT COLUNA 50 BAUMON FW010593 PT | AL6: =SUM(G6:AJ6) -> 0
A7: 3 | B7: 120010004 | C7: KIT COZINHA DE MADEIRA | D7: THB | E7: 374681 | F7: Kit 9P/1G Cozinha Baumon Açai CC/OW | AL7: =SUM(G7:AJ7) -> 0
A8: 4 | B8: 120010004 | C8: KIT COZINHA DE MADEIRA | D8: Kit´s Paraná | E8: 391650 | F8: Kit 8p/1G cozinha Baumon Cupuaçu FJ/SFT | AL8: =SUM(G8:AJ8) -> 0
A9: 5 | B9: 120003013 | C9: ROUP PORTA BASCULANTE ATÉ 4 PTS | D9: Demobille | E9: 358745 | F9: Roupeiro 4P/2G Baumon Coari 43240 Branco | AL9: =SUM(G9:AJ9) -> 0
A10: 6 | B10: 120003014 | C10: ROUP PORTA BASCULANTE DE 5 À 12 PTS | D10: Demobille | E10: 358746 | F10: Roupeiro 6P/2G Baumon Autazes 63220 CNM/OW | AL10: =SUM(G10:AJ10) -> 0
A11: 7 | B11: 120003014 | C11: ROUP PORTA BASCULANTE DE 5 À 12 PTS | D11: Demobille | E11: 358747 | F11: Roupeiro 6P/2G Baumon Maués 62560 CNM/OW | AL11: =SUM(G11:AJ11) -> 0
A12: 8 | B12: 120010003 | C12: BALCÃO COZINHA DE MADEIRA | D12: LInea | E12: 394619 | F12: BALC 2P BAUMON MANAÓS OW | AL12: =SUM(G12:AJ12) -> 0
A13: 9 | B13: 120010006 | C13: KIT FORNO DE MADEIRA | D13: LInea | E13: 394620 | F13: KIT FORNO 4P BAUMON MANAÓS OW | AL13: =SUM(G13:AJ13) -> 0
A14: 10 | B14: 120010002 | C14: ARMÁRIO AÉREO COZINHA DE MADEIRA | D14: LInea | E14: 395051 | F14: ARMÁRIO 2P BAUMON MANAÓS 810015116 OW | AL14: =SUM(G14:AJ14) -> 0
A15: 11 | B15: 120010002 | C15: ARMÁRIO AÉREO COZINHA DE MADEIRA | D15: LInea | E15: 395052 | F15: ARMÁRIO 2P BAUMON MANAÓS 810015117 OW | AL15: =SUM(G15:AJ15) -> 0
A16: 12 | B16: 120010003 | C16: BALCÃO COZINHA DE MADEIRA | D16: LInea | E16: 395053 | F16: BALC 2P/3G BAUMON MANAÓS C/TAMPO OW | AL16: =SUM(G16:AJ16) -> 0
... A27: 27 | B27: 111001017 | C27: LIQUIDIFICADOR ACIMA DE 3 VEL | D27: Mallory | E27: 400883 | F27: LIQUIDIFICADOR BAUMON BM1000 900W VM | AL27: =SUM(G27:AJ27) -> 0
A28: 28 | B28: 109001005 | C28: ENROLADO MOLA CASAL | D28: Herval | E28: 402152 | F28: COLC ENROLADO BAUMON C1972 138X188X30
A29: 29 | B29: 109001008 | C29: ENROLADO MOLA QUEEN | D29: Herval | E29: 402179 | F29: COLC ENROLADO BAUMON C1973 158X198X30
A30: 30 | B30: 109004006 | C30: CAMA AMERICANA QUEEN | D30: Herval | E30: 402247 | F30: CAMA AMERIC BAUMON CZ 158X198X28
A31: 31 | B31: 117004002 | C31: FOGÃO 4 BOCAS | D31: Mueller | E31: 406032 | F31: FOGÃO 4B BAUMON MESA INOX MFI4BB BR
A32: 32 | B32: 117004002 | C32: FOGÃO 4 BOCAS | D32: Mueller | E32: 406033 | F32: FOGÃO 4B BAUMON MESA VIDRO MFV4BB BR
A33: 33 | B33: 117004003 | C33: FOGÃO 5 BOCAS | D33: Mueller | E33: 406034 | F33: FOGÃO 5B BAUMON MESA INOX MFI5BB BR
A34: 34 | B34: 117004003 | C34: FOGÃO 5 BOCAS | D34: Mueller | E34: 406035 | F34: FOGÃO 5B BAUMON MESA VIDRO MFV5BB BR
A35: 35 | B35: 117004009 | C35: COOKTOP Á GÁS | D35: Mueller | E35: 406036 | F35: COOKTOP 5B BAUMON A GÁS MCG5BB PT
A36: 36 | B36: 117001017 | C36: CENTRÍFUGA LINHA BRANCA | D36: Mueller | E36: 406037 | F36: CENTRÍFUGA 15 BAUMON FIT 610008325 BR
A37: 37 | B37: 117007005 | C37: LAVADORA AUTOMÁTICA À PARTIR DE 12 KG | D37: Mueller | E37: 406038 | F37: LAVADORA 15 BAUMON 610008326 BR

Sheet Pedidos - Bemol Lovers
A2: Material | B2: Nome | C2: Pedido 19/03 | D2: Pedido 15/04 | E2: Pedido 08/06 | F2: Pedido 18/06 | J2: Total
A3: 374885 | B3: 1 PAR MEIA BEMOL BR LOGO AZ E LISTRA M | J3: =SUM(C3:I3) -> 0
A4: 374876 | B4: 1 PAR MEIA BEMOL AZ COM LOGO AZ M | J4: =SUM(C4:I4) -> 0
A5: 374873 | B5: 1 PAR MEIA BEMOL LISTRA AZ E VM M | J5: =SUM(C5:I5) -> 0
A6: 374879 | B6: 1 PAR MEIA BEMOL AZ COM LOGO BR M | J6: =SUM(C6:I6) -> 0
A7: 374882 | B7: 1 PAR MEIA BEMOL BRANCA COM LOGO AZ M | J7: =SUM(C7:I7) -> 0
A8: 374870 | B8: 1 PAR MEIA BEMOL COCAR M | D8: 600 | F8: 4000 | J8: =SUM(C8:I8) -> 4600
A9: 374867 | B9: 1 PAR MEIA BEMOL TEATRO AMAZONAS M | D9: 700 | F9: 4000 | J9: =SUM(C9:I9) -> 4700
A10: 374864 | B10: 1 PAR MEIA BEMOL BOTO COR DE RO M | D10: 1320 | F10: 4000 | J10: =SUM(C10:I10) -> 5320
A11: 374861 | B11: 1 PAR MEIA BEMOL CAPIVARA M | D11: 1820 | F11: 4000 | J11: =SUM(C11:I11) -> 5820
A12: 374875 | B12: 1 PAR MEIA BEMOL AZ COM LOGO AZ P | J12: =SUM(C12:I12) -> 0
A13: 374881 | B13: 1 PAR MEIA BEMOL BRANCA COM LOGO AZ P | J13: =SUM(C13:I13) -> 0
A14: 374878 | B14: 1 PAR MEIA BEMOL AZ COM LOGO BR P | J14: =SUM(C14:I14) -> 0
A15: 374888 | B15: 1 PAR MEIA BEMOL ONÇA PINTADA M | D15: 2070 | F15: 4000 | J15: =SUM(C15:I15) -> 6070
A16: 374884 | B16: 1 PAR MEIA BEMOL BR LOGO AZ E LISTRA P | D16: 500 | J16: =SUM(C16:I16) -> 500
A17: 374872 | B17: 1 PAR MEIA BEMOL LISTRA AZ E VM P | D17: 500 | J17: =SUM(C17:I17) -> 500
A18: 374858 | B18: 1 PAR MEIA BEMOL GATO PT M | D18: 2200 | F18: 4000 | J18: =SUM(C18:I18) -> 6200
A19: 374869 | B19: 1 PAR MEIA BEMOL COCAR P | C19: 1000 | F19: 4000 | J19: =SUM(C19:I19) -> 5000
A20: 374866 | B20: 1 PAR MEIA BEMOL TEATRO AMAZONAS P | C20: 1000 | D20: 500 | F20: 4000 | J20: =SUM(C20:I20) -> 5500
A21: 374863 | B21: 1 PAR MEIA BEMOL BOTO COR DE RO P | C21: 1000 | D21: 1230 | F21: 4000 | J21: =SUM(C21:I21) -> 6230
A22: 374857 | B22: 1 PAR MEIA BEMOL GATO PT P | D22: 2500 | F22: 4000 | J22: =SUM(C22:I22) -> 6500
A23: 374886 | B23: 1 PAR MEIA BEMOL BR LOGO AZ E LISTRA G | C23: 1000 | J23: =SUM(C23:I23) -> 1000
A24: 374887 | B24: 1 PAR MEIA BEMOL ONÇA PINTADA P | C24: 1000 | D24: 1660 | F24: 4000 | J24: =SUM(C24:I24) -> 6660
A25: 374883 | B25: 1 PAR MEIA BEMOL BRANCA COM LOGO AZ G | C25: 1000 | J25: =SUM(C25:I25) -> 1000
A26: 374880 | B26: 1 PAR MEIA BEMOL AZ COM LOGO BR G | C26: 1000 | J26: =SUM(C26:I26) -> 1000
A27: 374877 | B27: 1 PAR MEIA BEMOL AZ COM LOGO AZ G | C27: 1000 | J27: =SUM(C27:I27) -> 1000
A28: 374860 | B28: 1 PAR MEIA BEMOL CAPIVARA P | C28: 1600 | D28: 1500 | F28: 4000 | J28: =SUM(C28:I28) -> 7100
A29: 374874 | B29: 1 PAR MEIA BEMOL LISTRA AZ E VM G | C29: 1000 | D29: 500 | J29: =SUM(C29:I29) -> 1500
A30: 374868 | B30: 1 PAR MEIA BEMOL TEATRO AMAZONAS G | C30: 1000 | D30: 500 | F30: 4000 | J30: =SUM(C30:I30) -> 5500
A31: 374871 | B31: 1 PAR MEIA BEMOL COCAR G | C31: 1000 | D31: 500 | F31: 4000 | J31: =SUM(C31:I31) -> 5500
A32: 374865 | B32: 1 PAR MEIA BEMOL BOTO COR DE RO G | C32: 1000 | D32: 500 | F32: 4000 | J32: =SUM(C32:I32) -> 5500
A33: 374862 | B33: 1 PAR MEIA BEMOL CAPIVARA G | C33: 1200 | D33: 500 | F33: 4000 | J33: =SUM(C33:I33) -> 5700
A34: 374889 | B34: 1 PAR MEIA BEMOL ONÇA PINTADA G | C34: 1600 | D34: 500 | F34: 4000 | J34: =SUM(C34:I34) -> 6100
A35: 374859 | B35: 1 PAR MEIA BEMOL GATO PT G | C35: 2400 | F35: 4000
A36: 382306 | B36: Bola de futebol Bemol BL002 Br | E36: 800
A37: 382305 | B37: Bola de Futebol Bemol Recreativa Br | E37: 1200

Sheet Consolidado
A2: PROCESSOTIMBRO | B2: Pedido | C2: Produto | D2: Data do pedido | E2: Conclusãodeprodução | F2: Final | G2: HBL | H2: Ncontrole | I2: CIAMarítima | J2: Navio | K2: Valor | L2: ETD | M2: ETA | N2: Comentários
A3: BEMOL 5 | B3: 4508208614 | C3: AIRFRYER3,5L | D3: 45789 | E3: 45834 | F3: 45837 | G3: NBBLU25016330 | H3: MSDU7864062 | I3: MSC | J3: LOG-INEXPERIENCE/016S | K3: 5900 | L3: 45854 | M3: 45916 | N3: CONCLUÍDO
A4: BEMOL 6 | B4: 4508208616 | C4: LINHABEAUTY+ESPREMEDORBH3326 | D4: 45793 | E4: 45847 | F4: 45852 | G4: NBBLU25016481 | H4: MSNU9503623 | I4: MSC | J4: LOG-INEVOLUTION/042S | K4: 5900 | L4: 45879 | M4: 45930 | N4: CONCLUÍDO
A5: BEMOL 7 | B5: 4508208537 | C5: FERRO/ESPREMEDOR/VAPORIZADOR/CAÇAROLA | D5: 45793 | E5: 45854 | F5: 45855 | G5: NBBLU25016516 | H5: MSBU8716226 | I5: MSC | J5: LOG-INEVOLUTION/042S | K5: 5900 | L5: 45879 | M5: 45930 | N5: CONCLUÍDO
A6: BEMOL 11 | B6: 4508206547 | C6: AIRFRYER12L+SANDUICHEIRA | D6: 45838 | E6: 46262 | F6: 45898 | G6: NBBLU25017501 | H6: FDCU0035202 | I6: HapagLLoyd | J6: KUALALUMPUREXPRESS | K6: 4000 | L6: 45908 | M6: 45970 | N6: CONCLUÍDO
A7: BEMOL 8 | B7: 4508208626 | C7: LIQUIDIFICADORES+ COPO | D7: 45845 | E7: 45893 | F7: 45896 | G7: SNBLU25012968 | H7: UETU8288620 | I7: MSC | J7: MSCANTONELLAUX536A | K7: 4000 | L7: 45906 | M7: 45974 | N7: CONCLUÍDO
A8: BEMOL 12 | B8: 4508208624 | C8: LIQUIDIFICADORES+SANDUICHEIRA+MINIPR.+jUICERJE678G | D8: 45845 | E8: 45909 | F8: 45910 | G8: NBBLU25018167 | H8: ESHU7234223 | I8: Cosco | J8: COSCOSHIPPINGPENGBO/16 | K8: 4000 | L8: 45915 | M8: 45976 | N8: CONCLUÍDO
A9: BEMOL 9 | B9: 4508208633 | C9: VIDROSREPOSIÇÃO01 | D9: 45842 | E9: 45907 | F9: 45908 | G9: QOBLU25009926 | H9: MSNU9540355 | I9: MSC | J9: LOG-INEXPERIENCE/018S | K9: 3500 | L9: 45911 | M9: 45972 | N9: CONCLUÍDO
A10: BEMOL 13 | B10: 4508214286 | C10: FORNOELÉTRICO | D10: 45854 | E10: 45894 | F10: 45895 | G10: SNBLU25013124 | H10: TGBU7569191 | I10: MSC | J10: LOG-INPOLARIS/125S | K10: 3500 | L10: 45918 | M10: 45979 | N10: CONCLUÍDO
A11: BEMOL 14 | B11: 4508235799 | C11: VIDROSREPOSIÇÃO02 | D11: 45852 | E11: 45930 | F11: 45930 | G11: QOBLU25010198 | H11: MSBU8122306 MEDU7313566 | I11: nsolida | J11: LOG-INPOLARIS/125S | K11: 5800 | L11: 45961 | M11: 46013 | N11: CONCLUÍDO
A12: BEMOL 10 | B12: 4508360745 | C12: MÁQUINADEGELO+(3)SUPORTETV+LIQUIDIFICADORGSE019 | D12: 45876 | E12: 45928 | F12: 45929 | G12: NBBLU25018879 | H12: MSMU7127483 | I12: MSC | J12: MSCLORENZAUX541A | K12: 2900 | L12: 45947 | M12: 46020 | N12: CONCLUÍDO
A13: BEMOL 19 | B13: 4508591119 | C13: VIDROSREPOSIÇÃO3A-CTNR1 | D13: 45876 | E13: 45960 | F13: 45966 | G13: ONEYTA5RA9176400 | H13: ONEU1824259 | I13: ONE | J13: MANZANILLO | K13: 5202.53 | L13: 45989 | M13: 46051 | N13: CONCLUÍDO
A14: BEMOL 19 | B14: 4508591119 | C14: VIDROSREPOSIÇÃO3B-CTNR2 | D14: 45876 | E14: 45960 | F14: 45966 | G14: ONEYTA5RA9176400 | H14: ONEU1834365 | I14: ONE | J14: MANZANILLO | K14: 5202.53 | L14: 45989 | M14: 46051 | N14: CONCLUÍDO
A15: BEMOL 20 | B15: 4508436265 | C15: AIRFRYER12L+GRILL+FERROÀSECO | D15: 45908 | E15: 45966 | F15: 45975 | G15: SHYY25114820 | H15: ONEU6318757 | I15: ONE | K15: 2754 | L15: 45988 | M15: 46034 | N15: CONCLUÍDO
A16: BEMOL 21 | B16: 4508436285 | C16: VIDROSREPOSIÇÃO4+Led002 | D16: 45902 | E16: 45976 | F16: 45977 | G16: ONEYTA5RA5881300 | H16: TCNU6619092 | I16: ONE | K16: 2679 | L16: 45993 | M16: 46063 | N16: CONCLUÍDO
A17: BEMOL 25 | B17: 4508532679 | C17: BEBEDOUROBAUMONYLRLW2540TBSBR | D17: 45929 | E17: 45985 | F17: 26/112025 | G17: NBBLU25020450 | H17: FFAU2354768 | I17: MSC | J17: MSCKATRINAUX548A | K17: 2459.85 | L17: 45992 | M17: 46056 | N17: CONCLUÍDO
A18: BEMOL 25 | B18: 4508532679 | C18: BEBEDOUROBAUMONYLRLW2540LBBR+BEBEDOUROBAUMONYLRLW2540LBBPT | D18: 45929 | E18: 45985 | F18: 45987 | G18: NBBLU25020450 | H18: MEDU8128285 | I18: MSC | J18: MSCKATRINAUX548A | K18: 2459.85 | L18: 45992 | M18: 46056 | N18: CONCLUÍDO
A19: BEMOL 25 | B19: 4508532679 | C19: BEBEDOUROBAUMONYLRLW2540LBBR+BEBEDOUROBAUMONYLRLW2540LBBPT | D19: 45929 | E19: 45985 | F19: 45987 | G19: NBBLU25020450 | H19: MSMU6226537 | I19: MSC | J19: MSCKATRINAUX548A | K19: 2459.85 | L19: 45992 | M19: 46056 | N19: CONCLUÍDO
A20: BEMOL 25 | B20: 4508532679 | C20: BEBEDOUROBAUMONYLRLW2540LBBR+BEBEDOUROBAUMONYLRLW2540LBBPT | D20: 45929 | E20: 45985 | F20: 45987 | G20: NBBLU25020450 | H20: MSNU5842887 | I20: MSC | J20: MSCKATRINAUX548A | K20: 2459.85 | L20: 45992 | M20: 46056 | N20: CONCLUÍDO
A21: BEMOL 25 | B21: 4508532679 | C21: BEBEDOUROBAUMONYLRLW2540LBBR+BEBEDOUROBAUMONYLRLW2540LBBPT | D21: 45929 | E21: 45985 | F21: 45987 | G21: NBBLU25020450 | H21: TCLU7779400 | I21: MSC | J21: MSCKATRINAUX548A | K21: 2459.85 | L21: 45992 | M21: 46056 | N21: CONCLUÍDO
A22: BEMOL 25 | B22: 4508532679 | C22: BEBEDOUROBAUMONYLRLW2540LBBR+BEBEDOUROBAUMONYLRLW2540LBBPT | D22: 45929 | E22: 45985 | F22: 45987 | G22: NBBLU25020450 | H22: TCNU8726382 | I22: MSC | J22: MSCKATRINAUX548A | K22: 2459.85 | L22: 45992 | M22: 46056 | N22: CONCLUÍDO
A23: BEMOL 25 | B23: 4508532679 | C23: BEBEDOUROBAUMONYYLRLW2540LBSBR | D23: 45929 | E23: 45985 | F23: 45987 | G23: NBBLU25020450 | H23: UETU7070845 | I23: MSC | J23: MSCKATRINAUX548A | K23: 2459.85 | L23: 45992 | M23: 46056 | N23: CONCLUÍDO
A24: BEMOL 27 | B24: 4508417096 | C24: AIRFRYER3,5L | D24: 45971 | E24: 46013 | F24: 46013 | G24: NBBLU25020986 | H24: MSNU8455500 | I24: MSC | J24: MSCAURIGAUX552A | K24: 2663 | L24: 46026 | M24: 46084 | N24: CONCLUÍDO
A25: BEMOL 26 | B25: 4508490039 | C25: AIRFRYER12L | D25: 45971 | E25: 46000 | F25: 46002 | G25: NBBLU25020957 | H25: BMOU6778070 | I25: MSC | J25: MSCAURIGAUX552A | K25: 2663 | L25: 46026 | M25: 46084 | N25: CONCLUÍDO
A26: BEMOL 29 | B26: 4508490029 | C26: FERROAVAPOR+FRIGOBARHC46 | D26: 45973 | E26: 46007 | F26: 46007 | G26: NBBLU5020956 | H26: TCLU7890497 | I26: MSC | J26: MSCAURIGAUX552A | K26: 2663 | L26: 46026 | M26: 46084 | N26: CONCLUÍDO
A27: BEMOL 29 | B27: 4508490029 | C27: FERROAVAPOR+FRIGOBARHC46 | D27: 45973 | E27: 46006 | F27: 46007 | G27: NBBLU25020836 | H27: MSMU5480383 | I27: MSC | J27: MSCDENISSEXUX551A | K27: 2663 | L27: 46384 | M27: 46077 | N27: CONCLUÍDO
A28: BEMOL 22 | B28: 4508645458 | C28: Reposição05A-2Containers | D28: 45960 | E28: 46001 | F28: 46002 | G28: TAO31126537 | H28: MSDU5974230 | I28: MSC | K28: 2538.09 | L28: 46034 | M28: 46084 | N28: CONCLUÍDO
A29: BEMOL 23 | B29: 4508657825 | C29: Reposição05B | D29: 45960 | E29: 46011 | F29: 46012 | G29: TAO31126537 | H29: MEDU7602018 | I29: MSC | K29: 2538.09 | L29: 46034 | M29: 46084 | N29: CONCLUÍDO
A30: BEMOL 37 | B30: 4508696481 | C30: FORNOELÉTRICO | D30: 45992 | E30: 46021 | F30: 45677 | G30: CAN31112406 | H30: TGBU5940960 | I30: HAPAG-LLOYD | J30: MSCSARYA | K30: 2006 | L30: 46058 | M30: 46114 | N30: CONCLUÍDO
A31: BEMOL 37 | B31: 4508696481 | C31: FORNOELÉTRICO | D31: 45992 | E31: 46021 | F31: 45677 | G31: CAN31112406 | H31: FANU3854801 | I31: HAPAG-LLOYD | J31: MSCSARYA | K31: 2006 | L31: 46058 | M31: 46114 | N31: CONCLUÍDO
A32: BEMOL 31 | B32: 4508532742 | C32: REPOSIÇÃODEVIDROS6 | D32: 46006 | E32: 46052 | F32: 46052 | G32: CKBLU26005229 | H32: MSNU5267237 | I32: AMTRANS | K32: 2050 | L32: 46086 | M32: 46147 | N32: CONCLUÍDO
A33: BEMOL 33 | B33: 4508770727 | C33: BEAUTYEAIRFRYER3,5l | D33: 46006 | E33: 46096 | F33: 46097 | G33: CKBLU26005229 | H33: BMOU6580654 | I33: AMTRANS | K33: 2050 | L33: 46092 | M33: 46153 | N33: CONCLUÍDO
A34: BEMOL 35 | B34: 4508750228 | C34: FORNOELÉTRICO | D34: 46014 | E34: 46054 | F34: 46055 | G34: SZXS074568 | H34: MSMU4423326 | I34: MSC | J34: NCBREDA | K34: 1900 | L34: 46064 | M34: 46140 | N34: CONCLUÍDO
A35: BEMOL 35 | B35: 4508750228 | C35: FORNOELÉTRICO | D35: 46014 | E35: 46054 | F35: 46055 | G35: SZXS074568 | H35: MSDU5172851 | I35: MSC | J35: NCBREDA | K35: 1900 | L35: 46064 | M35: 46140 | N35: CONCLUÍDO
A36: BEMOL 35 | B36: 4508750228 | C36: FORNOELÉTRICO | D36: 46014 | E36: 46054 | F36: 46055 | G36: SZXS074568 | H36: TGBU4396106 | I36: MSC | J36: NCBREDA | K36: 1900 | L36: 46064 | M36: 46140 | N36: CONCLUÍDO
A37: BEMOL 35 | B37: 4508750228 | C37: FORNOELÉTRICO | D37: 46014 | E37: 46054 | F37: 46055 | G37: SZXS074568 | H37: MSMU6142797 | I37: MSC | J37: NCBREDA | K37: 1900 | L37: 46064 | M37: 46140 | N37: CONCLUÍDO
A38: BEMOL 35 | B38: 4508750228 | C38: FORNOELÉTRICO | D38: 46014 | E38: 46054 | F38: 46055 | G38: SZXS074568 | H38: MSMU6958287 | I38: MSC | J38: NCBREDA | K38: 1900 | L38: 46064 | M38: 46140 | N38: CONCLUÍDO
A39: BEMOL 35 | B39: 4508750228 | C39: FORNOELÉTRICO | D39: 46014 | E39: 46054 | F39: 46055 | G39: SZXS074568 | H39: MSDU6329101 | I39: MSC | J39: NCBREDA | K39: 1900 | L39: 46064 | M39: 46140 | N39: CONCLUÍDO
A40: BEMOL 34 | B40: 4508779388 | C40: REPOSIÇÃODEVIDRO7A | D40: 46014 | E40: 46049 | F40: 46050 | G40: SHA31176965 | H40: BMOU4956439 | I40: MSC | J40: ZHONGCHENG99 | K40: 2250 | L40: 46086 | M40: 46156 | N40: CONCLUÍDO
A41: BEMOL 34 | B41: 4508779388 | C41: REPOSIÇÃODEVIDRO7B | D41: 46014 | E41: 46049 | F41: 46050 | G41: SHA31176965 | H41: HAMU4323916 | I41: MSC | J41: ZHONGCHENG99 | K41: 2250 | L41: 46086 | M41: 46156 | N41: CONCLUÍDO
...

Sheet MRP IMP
A1: #VALUE! | D1: #VALUE! | F1: Data do pedido | G1: 46213 | H1: =_xlfn.XLOOKUP(H4,Consolidado!$A:$A,Consolidado!$D:$D) -> 46014 | I1: =_xlfn.XLOOKUP(I4,Consolidado!$A:$A,Consolidado!$D:$D) -> 46084 | J1: =_xlfn.XLOOKUP(J4,Consolidado!$A:$A,Consolidado!$D:$D) -> Novo desenvolvimento | K1: =_xlfn.XLOOKUP(K4,Consolidado!$A:$A,Consolidado!$D:$D) -> Novo desenvolvimento | L1: 46100 | M1: 46504 | N1: =_xlfn.XLOOKUP(N4,Consolidado!$A:$A,Consolidado!$D:$D) -> #N/A | O1: =_xlfn.XLOOKUP(O4,Consolidado!$A:$A,Consolidado!$D:$D) -> Novo desenvolvimento | P1: =_xlfn.XLOOKUP(P4,Consolidado!$A:$A,Consolidado!$D:$D) -> 46090 | Q1: =_xlfn.XLOOKUP(Q4,Consolidado!$A:$A,Consolidado!$D:$D) -> 46160 | R1: =_xlfn.XLOOKUP(R4,Consolidado!$A:$A,Consolidado!$D:$D) -> 46090 | S1: =_xlfn.XLOOKUP(S4,Consolidado!$A:$A,Consolidado!$D:$D) -> 46093 | T1: =_xlfn.XLOOKUP(T4,Consolidado!$A:$A,Consolidado!$D:$D) -> 46093 | U1: =_xlfn.XLOOKUP(U4,Consolidado!$A:$A,Consolidado!$D:$D) -> 46108 | ... AS1: =_xlfn.XLOOKUP(AS4,Consolidado!$A:$A,Consolidado!$D:$D) -> #N/A
F2: Saída - ETD | G2: =G1+45 -> 46258 | H2: 46092 | I2: 46064 | J2: 46126 | K2: =_xlfn.XLOOKUP(K4,Consolidado!$A:$A,Consolidado!$E:$E) -> 46234 | L2: =_xlfn.XLOOKUP(L4,Consolidado!$A:$A,Consolidado!$E:$E) -> #N/A | M2: =_xlfn.XLOOKUP(M4,Consolidado!$A:$A,Consolidado!$E:$E) -> #N/A | N2: =_xlfn.XLOOKUP(N4,Consolidado!$A:$A,Consolidado!$E:$E) -> #N/A | O2: =_xlfn.XLOOKUP(O4,Consolidado!$A:$A,Consolidado!$E:$E) -> 46249 | P2: =_xlfn.XLOOKUP(P4,Consolidado!$A:$A,Consolidado!$E:$E) -> 46139 | Q2: =_xlfn.XLOOKUP(Q4,Consolidado!$A:$A,Consolidado!$E:$E) -> 46226 | R2: =_xlfn.XLOOKUP(R4,Consolidado!$A:$A,Consolidado!$E:$E) -> 46150 | ... AS2: =_xlfn.XLOOKUP(AS4,Consolidado!$A:$A,Consolidado!$E:$E) -> #N/A
F3: Previsão de Chegada - ETA | G3: =G2+60 -> 46318 | H3: 46153 | I3: 46142 | J3: 46187 | K3: =K2+60 -> 46294 | L3: =L2+60 -> #N/A | M3: =M2+60 -> #N/A | N3: =N2+60 -> #N/A | O3: =O2+60 -> 46309 | P3: 46191 | Q3: =Q2+60 -> 46286 | R3: =R2+60 -> 46210 | S3: =S2+60 -> 46207 | T3: =T2+60 -> 46222 | U3: =U2+60 -> 46237 | V3: =V2+60 -> 46237 | W3: =W2+60 -> 46238 | X3: =X2+60 -> 46258 | ... AS3: =AS2+60 -> #N/A
A4: Qtd | B4: Categoria | C4: GM9 Descrição | D4: Trade | E4: Código | F4: Descrição | G4: PI-BAUMON-032026 | H4: Bemol 36 | I4: Bemol 38 | J4: Bemol 39 | K4: Bemol 41 | L4: Elox 01 19/03/2026 | M4: Elox 02 27/04/2027 | N4: Elox 03 05/06/2026 | O4: Bemol 43 | P4: Bemol 45 | Q4: Bemol 46 | R4: Bemol 47 | S4: Bemol 48 | T4: Bemol 49 | U4: Bemol 50 | V4: Bemol 51 | W4: Bemol 52 | X4: Bemol 53 | Y4: Bemol 54 | Z4: Bemol 55 | AA4: Bemol 56 | AB4: Bemol 57 | AC4: Bemol 58 | AD4: Bemol 59 | AE4: Bemol 60 | AF4: Bemol 61 | AG4: Bemol 62 | AH4: Bemol 63 | AI4: Bemol 64 | AJ4: Bemol 65 | AK4: Bemol 66 | AL4: Bemol 67 | AM4: Bemol 68 | AN4: Bemol 69 | AO4: Bemol 70 | AP4: Bemol 71 | AQ4: Bemol 72 | AR4: Bemol 73 | AS4: Bemol 74 | AT4: Acumulado
A5: 1 | B5: 111001012 | C5: FRITADEIRA | D5: Timbro | E5: 238697 | F5: FRITAD BAUMON AIR FRYER 35L YJ-613D PT | H5: 1628 | AB5: 1400 | AT5: =SUM(G5:AS5) -> 3028
A6: 2 | B6: 111001012 | C6: FRITADEIRA | D6: Timbro | E6: 238698 | F6: FRITAD BAUMON AIR FRYER 12L GSE021 PT | S6: 1112 | U6: 1150 | Y6: 1112 | AD6: 2224 | AF6: 476 | AL6: 2224 | AT6: =SUM(G6:AS6) -> 8298 | AW6: 373758 | AX6: 9000
A7: 3 | B7: 111001005 | C7: CAFETEIRA | D7: Timbro | E7: 238699 | F7: CAFETEIRA BAUMON 108TS PT/PR | AT7: =SUM(G7:AS7) -> 0 | AW7: 370451 | AX7: 5000
A8: 4 | B8: 111001020 | C8: SANDUICHEIRA | D8: Timbro | E8: 238700 | F8: SANDUICHEIRA BAUMON FS-8009C PT | H8: 3804 | T8: 3000 | AQ8: 3900 | AT8: =SUM(G8:AS8) -> 10704 | AW8: 370452 | AX8: 2000
A9: 5 | B9: 111001013 | C9: GRILL | D9: Timbro | E9: 238721 | F9: GRILL BAUMON 9228D PT | T9: 1920 | AB9: 2004 | AP9: 1920 | AT9: =SUM(G9:AS9) -> 5844 | AW9: 370453 | AX9: 2004
A10: 6 | B10: 111003005 | C10: FERRO SECO | D10: Timbro | E10: 238722 | F10: FERRO BAUMON SECO LM-209A AZ | H10: 2892 | AO10: 2400 | AT10: =SUM(G10:AS10) -> 5292 | AW10: 238700 | AX10: 3900
A11: 7 | B11: 111003001 | C11: FERRO À VAPOR | D11: Timbro | E11: 238723 | F11: FERRO BAUMON VAPOR LM-2262 AZ | AA11: 2400 | AO11: 2400 | AT11: =SUM(G11:AS11) -> 4800
A12: 8 | B12: 127001014 | C12: POTES | D12: Timbro | E12: 267869 | F12: POTE HERM BAUMON RET 400ML C/ TAMPA R145 | X12: 1008 | AT12: =SUM(G12:AS12) -> 1008
A13: 9 | B13: 127001014 | C13: POTES | D13: Timbro | E13: 267870 | F13: POTE HERM BAUMON RET 630ML C/ TAMPA R170 | X13: 12960 | AT13: =SUM(G13:AS13) -> 12960
A14: 10 | B14: 127001014 | C14: POTES | D14: Timbro | E14: 267931 | F14: POTE HERM BAUMON 1410ML R220-2FULL | AT14: =SUM(G14:AS14) -> 0
A15: 11 | B15: 127001014 | C15: POTES | D15: Timbro | E15: 267932 | F15: POTE HERM BAUMON 1040ML C/TAM R195-2FULL | AG15: 1872 | AT15: =SUM(G15:AS15) -> 1872
A16: 12 | B16: 127001014 | C16: POTES | D16: Timbro | E16: 267936 | F16: POTE HERM BAUMON QD 750ML C/TAMP S150-2 | X16: 1440 | AG16: 2304 | AT16: =SUM(G16:AS16) -> 3744
A17: 13 | B17: 127001014 | C17: POTES | D17: Timbro | E17: 267937 | F17: POTE HERM BAUMON RET1020ML C/TAMP S195-3 | AG17: 1512 | AT17: =SUM(G17:AS17) -> 1512
A18: 14 | B18: 127001014 | C18: POTES | D18: Timbro | E18: 267938 | F18: POTE HERM BAUMON RET1430ML C/TAMP R220-3 | V18: 2820 | AG18: 1572 | AT18: =SUM(G18:AS18) -> 4392
A19: 15 | B19: 127001002 | C19: ASSADEIRAS/FÔRMAS | D19: Timbro | E19: 267939 | F19: ASSAD BAUMON VDR RET1600ML C/TAMP GB1600 | AG19: 1512 | AT19: =SUM(G19:AS19) -> 1512
A20: 16 | B20: 127001002 | C20: ASSADEIRAS/FÔRMAS | D20: Timbro | E20: 267940 | F20: ASSAD BAUMON VIDRO OVAL 3000ML OVAL-3000 | AG20: 1500 | AT20: =SUM(G20:AS20) -> 1500
A21: 17 | B21: 127001002 | C21: ASSADEIRAS/FÔRMAS | D21: Timbro | E21: 267941 | F21: ASSAD BAUMON VIDRO QUAD 1800ML GB-S1800 | AT21: =SUM(G21:AS21) -> 0
A22: 18 | B22: 127001006 | C22: CAÇAROLA | D22: Timbro | E22: 267942 | F22: CAÇAROLA BAUMON VIDRO 1000ML GC-1000 | AT22: =SUM(G22:AS22) -> 0
A23: 19 | B23: 127001006 | C23: CAÇAROLA | D23: Timbro | E23: 267943 | F23: CAÇAROLA BAUMON VIDRO 1500ML GC-1500 | AG23: 1992 | AT23: =SUM(G23:AS23) -> 1992
A24: 20 | B24: 127001006 | C24: CAÇAROLA | D24: Timbro | E24: 267944 | F24: CAÇAROLA BAUMON VIDRO 2000ML GC-2000 | AG24: 2040 | AT24: =SUM(G24:AS24) -> 2040
A25: 21 | B25: 127001002 | C25: ASSADEIRAS/FÔRMAS | D25: Timbro | E25: 267945 | F25: ASSADEIRA BAUMON VIDRO 1800ML GC-O1800 | AT25: =SUM(G25:AS25) -> 0
A26: 22 | B26: 127001001 | C26: ACESSÓRIOS DE COZINHA | D26: Timbro | E26: 267946 | F26: COPO MEDIDOR BAUMON VDR 500ML LB-500P | AG26: 1500 | AT26: =SUM(G26:AS26) -> 1500
A27: 23 | B27: 127001001 | C27: ACESSÓRIOS DE COZINHA | D27: Timbro | E27: 267947 | F27: COPO MEDIDOR BAUMON VDR 1000ML LB-1000P | AG27: 1584 | AT27: =SUM(G27:AS27) -> 1584
A28: 24 | B28: 127001014 | C28: POTES | D28: Timbro | E28: 268132 | F28: POTE HERM BAUMON RET 2260ML C/TAMP JL002 | V28: 2820 | X28: 7824 | AT28: =SUM(G28:AS28) -> 10644
A29: 25 | B29: 127001014 | C29: POTES | D29: Timbro | E29: 268133 | F29: POTE HERM BAUMON 1040ML C/TAMP R195 | X29: 4704 | AT29: =SUM(G29:AS29) -> 4704
A30: 26 | B30: 127001014 | C30: POTES | D30: Timbro | E30: 269686 | F30: POTE HERM BAUMON RET 630ML R170-2FULL AZ | AG30: 1512 | AT30: =SUM(G30:AS30) -> 1512
A31: 27 | B31: 127001002 | C31: ASSADEIRAS/FÔRMAS | D31: Timbro | E31: 367983 | F31: ASSADEIRA BAUMON OVAL 2800ML GC-02800 | V31: 2802 | X31: 9030 | AT31: =SUM(G31:AS31) -> 11832
A32: 28 | B32: 127001002 | C32: ASSADEIRAS/FÔRMAS | D32: Timbro | E32: 367984 | F32: ASSADEIRA BAUMON OVAL 2400ML GC-2400 | V32: 2802 | X32: 3588 | AT32: =SUM(G32:AS32) -> 6390
A33: 29 | B33: 127001027 | C33: SALADEIRAS/SOPEIRAS | D33: Timbro | E33: 367985 | F33: SALADEIRA BAUMON 880ML S880B-S | AT33: =SUM(G33:AS33) -> 0
A34: 30 | B34: 127001027 | C34: SALADEIRAS/SOPEIRAS | D34: Timbro | E34: 367986 | F34: SALADEIRA BAUMON 2400ML S2400B-S | AT34: =SUM(G34:AS34) -> 0
A35: 31 | B35: 127001027 | C35: SALADEIRAS/SOPEIRAS | D35: Timbro | E35: 367987 | F35: SALADEIRA BAUMON 3300ML S3300B-S | AT35: =SUM(G35:AS35) -> 0
A36: 32 | B36: 127001003 | C36: BANDEJAS/TRAVESSAS/BAIXELAS | D36: Timbro | E36: 383492 | F36: TRAVESSA BAUMON OVAL VIDRO C/TAMPA 2,4L | U36: 1254 | AT36: =SUM(G36:AS36) -> 1254
A37: 33 | B37: 127001003 | C37: BANDEJAS/TRAVESSAS/BAIXELAS | D37: Timbro | E37: 383493 | F37: TRAVESSA BAUMON OVAL VIDRO C/TAMPA 3L | AT37: =SUM(G37:AS37) -> 0
A38: 34 | B38: 127001003 | C38: BANDEJAS/TRAVESSAS/BAIXELAS | D38: Timbro | E38: 383494 | F38: TRAVESSA BAUMON OVAL VIDRO C/TAMPA 4L | U38: 420 | AT38: =SUM(G38:AS38) -> 420
A39: 35 | B39: 127001003 | C39: BANDEJAS/TRAVESSAS/BAIXELAS | D39: Timbro | E39: 383495 | F39: TRAVESSA BAUMON RETANGULAR C/TAMPA 1,6L | AT39: =SUM(G39:AS39) -> 0
A40: 36 | B40: 127001003 | C40: BANDEJAS/TRAVESSAS/BAIXELAS | D40: Timbro | E40: 383496 | F40: TRAVESSA BAUMON RETANGULAR C/TAMPA 2,2L | AT40: =SUM(G40:AS40) -> 0
...

Sheet Base de Dados
A1: Qtd | B1: Forn. | C1: Pedido de compra | D1: INVOICE | E1: HBL | F1: Container | G1: Variedade de SKU | H1: Produtos | I1: Profundidade de SKU Container | J1: Custo em Dólar ($) | K1: Processo | L1: Modal | M1: Valor Mercadoria (R$) | N1: Frete (R$) | O1: Seguro (R$) | P1: SISCOMEX | Q1: Despachante | R1: Frete Local | S1: COFINS | T1: PIS | U1: Total | V1: % Frete | W1: Localização | X1: Status | Y1: DIAS ATÉ CHEGADA | Z1: ESTIMATIVA CHEGADA | AA1: PRONTIDÃO
A2: 1 | B2: TIMBRO SWISS SA | C2: 4508010244 | D2: BEMOL003A | E2: NBOMAU25010624 | F2: MSMU4593106 | G2: =COUNTIF(Precificação!A:A,'Base de Dados'!D25) -> 7 | H2: CAFETEIRA , SANDUICHEIRA E GRILL | I2: =SUMIF(Precificação!A:A,D2,Precificação!F:F) -> 7074 | J2: 58189.26 | K2: 2025000082 | L2: Marítimo | M2: 330817.58 | N2: 36953.8 | O2: 181.93 | P2: 192.79 | Q2: 1537.1 | R2: 1300 | S2: 35507.49 | T2: 7727.02 | U2: =SUM(M2:T2) -> 414217.71 | V2: =N2/M2 -> 0.11170446 | W2: CHINA | X2: =IF(K2<>"", "CONCLUÍDO", IF(E2<>"", "EM TRÂNSITO", "EM PRODUÇÃO")) -> CONCLUÍDO | Z2: 46026
A3: =A2+1 -> 2 | B3: TIMBRO SWISS SA | C3: 4508031503 | D3: BEMOL003B | E3: NBOMAU25010647 | F3: MSBU8251514 | G3: =COUNTIF(Precificação!A:A,'Base de Dados'!D26) -> 1 | H3: CAFETEIRA ,FERROS E GRILL | I3: =SUMIF(Precificação!A:A,D3,Precificação!F:F) -> 8630 | J3: 62940.5 | K3: 2025000097 | L3: Marítimo | M3: 361416.94 | N3: 37324.3 | O3: 198.79 | P3: 254.49 | Q3: 1537.1 | R3: 1300 | S3: 38497.72 | T3: 8377.74 | U3: =SUM(M3:T3) -> 448907.08 | V3: =N3/M3 -> 0.10327214 | W3: CHINA | X3: =IF(K3<>"", "CONCLUÍDO", IF(E3<>"", "EM TRÂNSITO", "EM PRODUÇÃO")) -> CONCLUÍDO | Z3: 46026
A4: =A3+1 -> 3 | B4: TIMBRO SWISS SA | C4: 4508173581 | D4: BEMOL004 | E4: NBOMAU25040862 | F4: MEDU4437814/ MSNU7504404 | G4: =COUNTIF(Precificação!A:A,'Base de Dados'!D27) -> 15 | H4: VIDROS BAUMON | I4: =SUMIF(Precificação!A:A,D4,Precificação!F:F) -> 37782 | J4: 68555.52 | K4: 2025000164 | L4: Marítimo | M4: 378515.59 | N4: 29815.02 | O4: 208.15 | P4: 254.49 | Q4: 1537.1 | R4: 1300 | S4: 39423.99 | T4: 8579.32 | U4: =SUM(M4:T4) -> 459633.66 | V4: =N4/M4 -> 0.078768275 | W4: CHINA | X4: =IF(K4<>"", "CONCLUÍDO", IF(E4<>"", "EM TRÂNSITO", "EM PRODUÇÃO")) -> CONCLUÍDO | Z4: 46026
A5: =A4+1 -> 4 | B5: TIMBRO SWISS SA | C5: 4508529711 | D5: BEMOL 10 | E5: NBBLU25018879 | F5: MSMU7127483 | G5: =COUNTIF(Precificação!A:A,'Base de Dados'!D23) -> 7 | H5: MÁQ. DE GELO + (3) SUP DE TV + MINI PROC + ESPREMEDOR | I5: =SUMIF(Precificação!A:A,D5,Precificação!F:F) -> 18234 | J5: 86089.58 | K5: 2026000006 | L5: Marítimo | M5: 464528.27 | N5: 16164.31 | O5: 255.51 | P5: 254.49 | Q5: 1549 | R5: 1300 | S5: 46411.46 | T5: 10099.89 | U5: =SUM(M5:T5) -> 540562.93 | V5: =N5/M5 -> 0.034797258 | W5: CHINA | X5: =IF(K5<>"", "CONCLUÍDO", IF(E5<>"", "EM TRÂNSITO", "EM PRODUÇÃO")) -> CONCLUÍDO | Z5: 45988
A6: =A5+1 -> 5 | B6: TIMBRO SWISS SA | C6: 4508525585 | D6: BEMOL 14 | E6: QOBLU25010198 | F6: MSBU8122306/ MEDU8122306 | G6: =COUNTIF(Precificação!A:A,'Base de Dados'!D22) -> 1 | H6: VIDROS BOROSSILICATO - REPOSIÇÃO 02 | I6: =SUMIF(Precificação!A:A,D6,Precificação!F:F) -> 24720 | J6: 56730.42 | K6: 2026000001 | L6: Marítimo | M6: 314224.12 | N6: 32125.62 | O6: 172.81 | P6: 192.79 | Q6: 1549 | R6: 1300 | S6: 33439.42 | T6: 7276.97 | U6: =SUM(M6:T6) -> 390280.73 | V6: =N6/M6 -> 0.10223792 | W6: CHINA | X6: =IF(K6<>"", "CONCLUÍDO", IF(E6<>"", "EM TRÂNSITO", "EM PRODUÇÃO")) -> CONCLUÍDO | Z6: 45990
A7: =A6+1 -> 6 | B7: TIMBRO SWISS SA | C7: 4508684160 | D7: BEMOL 17 | E7: KHI1847MUN | F7: HAMU2329387 | G7: =COUNTIF(Precificação!A:A,'Base de Dados'!D13) -> 10 | H7: JOGO DE CAMA | I7: =SUMIF(Precificação!A:A,D7,Precificação!F:F) -> 10800 | J7: 103783.24 | K7: 2026000103 | L7: Marítimo | M7: 542869.37 | N7: 15200.7 | O7: 298.57 | P7: 192.79 | Q7: 1537.1 | R7: 1300 | S7: 57232.81 | T7: 11725.75 | U7: =SUM(M7:T7) -> 630357.09 | V7: =N7/M7 -> 0.028000659 | W7: CHINA | X7: =IF(K7<>"", "CONCLUÍDO", IF(E7<>"", "EM TRÂNSITO", "EM PRODUÇÃO")) -> CONCLUÍDO | Z7: 46020
A8: =A7+1 -> 7 | B8: TIMBRO SWISS SA | C8: 4508624477 | D8: BEMOL 18 | E8: I245708 | F8: SEM CTN | G8: =COUNTIF(Precificação!A:A,'Base de Dados'!D3) -> 4 | H8: LENÇÓIS BAUMON | I8: =SUMIF(Precificação!A:A,D8,Precificação!F:F) -> 2564 | J8: 42092.08 | K8: 2026000062 | L8: Aéreo | M8: 218904.07 | N8: 31063.2 | O8: 117.64 | P8: 154.23 | Q8: 1537.1 | R8: 1300 | S8: 20109.87 | T8: 4120.05 | U8: =SUM(M8:T8) -> 277306.16 | V8: =N8/M8 -> 0.14190325 | W8: CHINA | X8: =IF(K8<>"", "CONCLUÍDO", IF(E8<>"", "EM TRÂNSITO", "EM PRODUÇÃO")) -> CONCLUÍDO | Z8: 46020
A9: =A8+1 -> 8 | B9: TIMBRO SWISS SA | C9: 4508591119 | D9: BEMOL 19 | E9: KDBW25110028 | F9: ONEU1824259 | G9: =COUNTIF(Precificação!A:A,'Base de Dados'!D2) -> 3 | H9: POTES/TRAVESSAS/SALEIRAS | I9: =SUMIF(Precificação!A:A,D9,Precificação!F:F) -> 33816 | J9: 63051.04 | K9: 2026000040 | L9: Marítimo | M9: 326843.98 | N9: 27007.6 | O9: 117.64 | P9: 154.23 | Q9: 1537.1 | R9: 1300 | S9: 20109.87 | T9: 4120.05 | U9: =SUM(M9:T9) -> 381190.47 | V9: =N9/M9 -> 0.082631475 | W9: CHINA | X9: =IF(K9<>"", "CONCLUÍDO", IF(E9<>"", "EM TRÂNSITO", "EM PRODUÇÃO")) -> CONCLUÍDO | Z9: 46020
A10: =A9+1 -> 9 | B10: TIMBRO SWISS SA | C10: 4508436265 | D10: BEMOL 20 | E10: SHYY25114820 | F10: ONEU6318757 | G10: =COUNTIF(Precificação!A:A,'Base de Dados'!D24) -> 2 | H10: FRITADEIRA AIR FRYER 12 L + SANDUICHEIRA + FERRO SECO | I10: =SUMIF(Precificação!A:A,D10,Precificação!F:F) -> 6104 | J10: 57048.8 | K10: 2026000015 | L10: Marítimo | M10: 359379.14 | N10: 14506.06 | O10: 168.71 | P10: 223.64 | Q10: 1549 | R10: 1300 | S10: 31014.33 | T10: 6749.23 | U10: =SUM(M10:T10) -> 414890.11 | V10: =N10/M10 -> 0.040364224 | W10: CHINA | X10: =IF(K10<>"", "CONCLUÍDO", IF(E10<>"", "EM TRÂNSITO", "EM PRODUÇÃO")) -> CONCLUÍDO | Z10: 46026
A11: =A10+1 -> 10 | B11: TIMBRO SWISS SA | C11: 4508615909 | D11: BEMOL 21 | E11: KDBW25110063 | F11: TCNU6619092 | G11: =COUNTIF(Precificação!A:A,'Base de Dados'!D8) -> 4 | H11: VIDROS REPOSIÇÃO 4 + LED 002 | I11: =SUMIF(Precificação!A:A,D11,Precificação!F:F) -> 22384 | J11: 50232.4 | K11: 2026000053 | L11: Marítimo | M11: 262655.17 | N11: 12026.24 | O11: 144.47 | P11: 192.79 | Q11: 1537.1 | R11: 1300 | S11: 131724.89 | T11: 28665.51 | U11: =SUM(M11:T11) -> 438246.17 | V11: =N11/M11 -> 0.045787182 | W11: CHINA | X11: =IF(K11<>"", "CONCLUÍDO", IF(E11<>"", "EM TRÂNSITO", "EM PRODUÇÃO")) -> CONCLUÍDO | Z11: 46036
A12: =A11+1 -> 11 | B12: TIMBRO SWISS SA | C12: 4508645458 | D12: BEMOL 22 | E12: TAO31126537 | F12: MEDU7602018 / BMOU6778070 | G12: =COUNTIF(Precificação!A:A,'Base de Dados'!D11) -> 7 | H12: RECOMPRA VIDRO | I12: =SUMIF(Precificação!A:A,D12,Precificação!F:F) -> 28042 | J12: 62843.66 | K12: 2026000080 | L12: Marítimo | M12: 332254.43 | N12: 24225.03 | O12: 212.06 | P12: 192.79 | Q12: 1537.1 | R12: 1300 | S12: 34420.73 | T12: 7490.52 | U12: =SUM(M12:T12) -> 401632.66 | V12: =N12/M12 -> 0.072911082 | W12: CHINA | X12: =IF(K12<>"", "CONCLUÍDO", IF(E12<>"", "EM TRÂNSITO", "EM PRODUÇÃO")) -> CONCLUÍDO | Z12: 46061
A13: =A12+1 -> 12 | B13: TIMBRO SWISS SA | C13: 4508657825 | D13: BEMOL 23 | E13: TAO31126540 | F13: MSDU7322380 | G13: =COUNTIF(Precificação!A:A,'Base de Dados'!D12) -> 15 | H13: RECOMPRA VIDRO | I13: =SUMIF(Precificação!A:A,D13,Precificação!F:F) -> 20752 | J13: 34978.32 | K13: 2026000086 | L13: Marítimo | M13: 168515.84 | N13: 12027.03 | O13: 107.32 | P13: 154.23 | Q13: 1537.1 | R13: 1300 | S13: 17432.74 | T13: 3793.64 | U13: =SUM(M13:T13) -> 204867.9 | V13: =N13/M13 -> 0.071370323 | W13: CHINA | X13: =IF(K13<>"", "CONCLUÍDO", IF(E13<>"", "EM TRÂNSITO", "EM PRODUÇÃO")) -> CONCLUÍDO | Z13: 46071
A14: =A13+1 -> 13 | B14: TIMBRO SWISS SA | C14: 4508803268 | D14: BEMOL 24 | E14: KHI1874MUN | F14: FANU3705454 | G14: =COUNTIF(Precificação!A:A,'Base de Dados'!D17) -> 1 | H14: CAMA, MESA E BANHO | I14: =SUMIF(Precificação!A:A,D14,Precificação!F:F) -> 10436 | J14: 61996.38 | K14: 2026000140 | L14: Marítimo | M14: 303776.06 | N14: 14484.1 | O14: 167.09 | P14: 154.23 | Q14: 1537.1 | R14: 1300 | S14: 32638.79 | T14: 6686.97 | U14: =SUM(M14:T14) -> 360744.34 | V14: =N14/M14 -> 0.047680189 | W14: CHINA | X14: =IF(K14<>"", "CONCLUÍDO", IF(E14<>"", "EM TRÂNSITO", "EM PRODUÇÃO")) -> CONCLUÍDO | Z14: 46112
A15: =A14+1 -> 14 | B15: TIMBRO SWISS SA | C15: 4508532679 | D15: BEMOL 25 | E15: NBBLU25020450 | F15: FFAU2354768/ MEDU8128285/ MSMU6226537/MSNU5842887/ TCLU7779400/ TCNU8726382/ UETU7070845 | G15: =COUNTIF(Precificação!A:A,'Base de Dados'!D5) -> 5 | H15: BEBEDOUROS | I15: =SUMIF(Precificação!A:A,D15,Precificação!F:F) -> 5595 | J15: 243932.75 | K15: 2026000045 | L15: Marítimo | M15: 691179.5 | N15: 77292.6 | O15: 705.41 | P15: 223.64 | Q15: 1537.1 | R15: 1300 | S15: 131724.92 | T15: 28665.53 | U15: =SUM(M15:T15) -> 932628.7 | V15: =N15/M15 -> 0.1118271 | W15: CHINA | X15: =IF(K15<>"", "CONCLUÍDO", IF(E15<>"", "EM TRÂNSITO", "EM PRODUÇÃO")) -> CONCLUÍDO | Z15: 46045
A16: =A15+1 -> 15 | B16: TIMBRO SWISS SA | C16: 4508642248 | D16: BEMOL 26 | E16: NBBLU25020957 | F16: BMOU6778070 | G16: =COUNTIF(Precificação!A:A,'Base de Dados'!D7) -> 17 | H16: AIRFRYER 12L | I16: =SUMIF(Precificação!A:A,D16,Precificação!F:F) -> 1112 | J16: 42044.72 | K16: 2026000074 | L16: Marítimo | M16: 222290.43 | N16: 12551.5 | O16: 122.24 | P16: 154.23 | Q16: 1537.1 | R16: 1300 | S16: 22674.04 | T16: 4934.25 | U16: =SUM(M16:T16) -> 265563.79 | V16: =N16/M16 -> 0.056464419 | W16: CHINA | X16: =IF(K16<>"", "CONCLUÍDO", IF(E16<>"", "EM TRÂNSITO", "EM PRODUÇÃO")) -> CONCLUÍDO | Z16: 46060
A17: =A16+1 -> 16 | B17: TIMBRO SWISS SA | C17: 4508642952 | D17: BEMOL 27 | E17: NBBLU25020986 | F17: MSNU8455500 | G17: =COUNTIF(Precificação!A:A,'Base de Dados'!D9) -> 15 | H17: AIRFRYER 3,5L | I17: =SUMIF(Precificação!A:A,D17,Precificação!F:F) -> 2112 | J17: 36072.96 | K17: 2026000077 | L17: Marítimo | M17: 190717.74 | N17: 12270.97 | O17: 104.89 | P17: 154.23 | Q17: 1537.1 | R17: 1300 | S17: 19598.53 | T17: 4264.97 | U17: =SUM(M17:T17) -> 229948.43 | V17: =N17/M17 -> 0.064340999 | W17: CHINA | X17: =IF(K17<>"", "CONCLUÍDO", IF(E17<>"", "EM TRÂNSITO", "EM PRODUÇÃO")) -> CONCLUÍDO | Z17: 46073
A18: =A17+1 -> 17 | B18: TIMBRO SWISS SA | C18: 4508628310 | D18: BEMOL 28 | E18: NBBLU25020836 | F18: MSMU5480383 | G18: =COUNTIF(Precificação!A:A,'Base de Dados'!D6) -> 14 | H18: FRIGOBAR | I18: =SUMIF(Precificação!A:A,D18,Precificação!F:F) -> 575 | J18: 28359 | K18: 2026000068 | L18: Marítimo | M18: 146564.98 | N18: 12002.01 | O18: 80.62 | P18: 154.23 | Q18: 1537.1 | R18: 1300 | S18: 15309.49 | T18: 3331.6 | U18: =SUM(M18:T18) -> 180280.03 | V18: =N18/M18 -> 0.081888661 | W18: CHINA | X18: =IF(K18<>"", "CONCLUÍDO", IF(E18<>"", "EM TRÂNSITO", "EM PRODUÇÃO")) -> CONCLUÍDO | Z18: 46020
A19: =A18+1 -> 18 | B19: TIMBRO SWISS SA | C19: 4508645302 | D19: BEMOL 29 | E19: NBBLU25020956 | F19: TCLU7890497 | G19: =COUNTIF(Precificação!A:A,'Base de Dados'!D10) -> 3 | H19: FRIGOBAR HC46 + FERRO A VAPOR | I19: =SUMIF(Precificação!A:A,D19,Precificação!F:F) -> 2525 | J19: 32826 | K19: 2026000078 | L19: Marítimo | M19: 173551.06 | N19: 11102.7 | O19: 95.43 | P19: 192.79 | Q19: 1537.1 | R19: 1300 | S19: 17966.7 | T19: 3909.85 | U19: =SUM(M19:T19) -> 209655.63 | V19: =N19/M19 -> 0.06397368 | W19: CHINA | X19: =IF(K19<>"", "CONCLUÍDO", IF(E19<>"", "EM TRÂNSITO", "EM PRODUÇÃO")) -> CONCLUÍDO | Z19: 46067
A20: =A19+1 -> 19 | B20: TIMBRO SWISS SA | C20: 4508532742 | D20: BEMOL 31 | E20: CKBLU26005229 | F20: BMOU6580654/MSNU5267237 | G20: =COUNTIF(Precificação!A:A,'Base de Dados'!D16) -> 1 | H20: 9 POTES DE VIDRO | I20: =SUMIF(Precificação!A:A,D20,Precificação!F:F) -> 42972 | J20: 69733.56 | K20: 2026000132 | L20: Marítimo | M20: 345787.8 | N20: 23048.04 | O20: 190.17 | P20: 192.79 | Q20: 1537.1 | R20: 1300 | S20: 35611 | T20: 7749.54 | U20: =SUM(M20:T20) -> 415416.44 | V20: =N20/M20 -> 0.066653711 | W20: CHINA | X20: =IF(K20<>"", "CONCLUÍDO", IF(E20<>"", "EM TRÂNSITO", "EM PRODUÇÃO")) -> CONCLUÍDO | Z20: 46112
A21: =A20+1 -> 20 | B21: TIMBRO SWISS SA | C21: 4508626352 | D21: BEMOL 32 | E21: MFS-193 | F21: MFS-193 | G21: =COUNTIF(Precificação!A:A,'Base de Dados'!D4) -> 19 | H21: LENÇÓIS | I21: =SUMIF(Precificação!A:A,D21,Precificação!F:F) -> 2442 | J21: 13618.8 | K21: 2026000064 | L21: Aéreo | M21: 70825.93 | N21: 125250.42 | O21: 117.64 | P21: 154.23 | Q21: 1537.1 | R21: 1300 | S21: 20109.87 | T21: 4120.05 | U21: =SUM(M21:T21) -> 223415.24 | V21: =N21/M21 -> 1.7684261 | W21: CHINA | X21: =IF(K21<>"", "CONCLUÍDO", IF(E21<>"", "EM TRÂNSITO", "EM PRODUÇÃO")) -> CONCLUÍDO | Z21: 46020
A22: =A21+1 -> 21 | B22: TIMBRO SWISS SA | C22: 4508770727 | D22: BEMOL 33 | E22: NGB31164863 | F22: TGBU6867268 | G22: =COUNTIF(Precificação!A:A,'Base de Dados'!D18) -> 1 | H22: AIR FREYER | I22: =SUMIF(Precificação!A:A,D22,Precificação!F:F) -> 2112 | J22: 36072.96 | K22: 2026000148 | L22: Marítimo | M22: 179675.81 | N22: 14599.02 | O22: 115.66 | P22: 154.23 | Q22: 1537.1 | R22: 1300 | S22: 18758.68 | T22: 4082.2 | U22: =SUM(M22:T22) -> 220222.7 | V22: =N22/M22 -> 0.081252006 | W22: CHINA | X22: =IF(K22<>"", "CONCLUÍDO", IF(E22<>"", "EM TRÂNSITO", "EM PRODUÇÃO")) -> CONCLUÍDO | Z22: 46156
A23: =A22+1 -> 22 | B23: TIMBRO SWISS SA | C23: 4508779388 | D23: BEMOL 34 | E23: SHA31176965 | F23: HAMU4323916/BMOU4956439 | G23: =COUNTIF(Precificação!A:A,'Base de Dados'!D19) -> 2 | H23: VIDROS REP BAUMON | I23: =SUMIF(Precificação!A:A,D23,Precificação!F:F) -> 31572 | J23: 65027.52 | K23: 2026000152 | L23: Marítimo | M23: 327595.64 | N23: 27204.12 | O23: 180 | P23: 154.23 | Q23: 1537.1 | R23: 1300 | S23: 34255.57 | T23: 7454.59 | U23: =SUM(M23:T23) -> 399681.25 | V23: =N23/M23 -> 0.083041765 | W23: CHINA | X23: =IF(K23<>"", "CONCLUÍDO", IF(E23<>"", "EM TRÂNSITO", "EM PRODUÇÃO")) -> CONCLUÍDO | Z23: 46109
A24: =A23+1 -> 23 | B24: TIMBRO SWISS SA | C24: 4508750228 | D24: BEMOL 35 | E24: SZXS074568 | F24: MSDU5172851 MSDU6329101 MSMU4423326 MSMU6142797 MSMU6958287 TGBU4396106 | G24: =COUNTIF(Precificação!A:A,'Base de Dados'!D15) -> 9 | H24: POTES | I24: =SUMIF(Precificação!A:A,D24,Precificação!F:F) -> 6632 | J24: 110222.68 | K24: 2026000133 | L24: Marítimo | M24: 546561.2 | N24: 60618.32 | O24: 300.6 | P24: 192.79 | Q24: 1537.1 | R24: 1300 | S24: 58621.94 | T24: 12757.08 | U24: =SUM(M24:T24) -> 681889.03 | V24: =N24/M24 -> 0.11090857 | W24: CHINA | X24: =IF(K24<>"", "CONCLUÍDO", IF(E24<>"", "EM TRÂNSITO", "EM PRODUÇÃO")) -> CONCLUÍDO | Z24: 46020
A25: =A24+1 -> 24 | B25: TIMBRO SWISS SA | C25: 4508751729 | D25: BEMOL 36 | E25: NGB31166038 | F25: HAMU1718065/ HLXU8221843 | G25: =COUNTIF(Precificação!A:A,'Base de Dados'!D28) -> 1 | H25: AIR FRYER 3,5L + PROCESSADOR+ SANDUICHEIRA+ FERRO+ CHAPINHA | I25: =SUMIF(Precificação!A:A,D25,Precificação!F:F) -> 20588 | J25: 134205.56 | K25: 2026000217 | L25: Marítimo | M25: 686810.37 | N25: 28719.97 | O25: 427.47 | P25: 331.62 | Q25: 1537.1 | R25: 1500 | S25: 69089.89 | T25: 15035.08 | U25: =SUM(M25:T25) -> 803451.5 | V25: =N25/M25 -> 0.041816448 | W25: CHINA | X25: =IF(K25<>"", "CONCLUÍDO", IF(E25<>"", "EM TRÂNSITO", "EM PRODUÇÃO")) -> CONCLUÍDO | Z25: 46150
A26: =A25+1 -> 25 | B26: TIMBRO SWISS SA | C26: 4508696481 | D26: BEMOL 37 | E26: CAN31112406 | F26: TGBU5940960/FANU3854801 | G26: =COUNTIF(Precificação!A:A,'Base de Dados'!D14) -> 18 | H26: FORNO ELÉTRICO 46L | I26: =SUMIF(Precificação!A:A,D26,Precificação!F:F) -> 1282 | J26: 39524.06 | K26: 2026000106 | L26: Marítimo | M26: 204161.53 | N26: 20723.99 | O26: 112.3 | P26: 154.23 | Q26: 1537.1 | R26: 1300 | S26: 21712.29 | T26: 4724.95 | U26: =SUM(M26:T26) -> 254426.39 | V26: =N26/M26 -> 0.10150781 | W26: CHINA | X26: =IF(K26<>"", "CONCLUÍDO", IF(E26<>"", "EM TRÂNSITO", "EM PRODUÇÃO")) -> CONCLUÍDO | Z26: 46081
A27: =A26+1 -> 26 | B27: TIMBRO SWISS SA | C27: 4508840421 | D27: BEMOL 38 | E27: KHI2062MUN | F27: TCNU6401006 | G27: =COUNTIF(Precificação!A:A,'Base de Dados'!D31) -> 6 | H27: CAMA, MESA E BANHO | I27: =SUMIF(Precificação!A:A,D27,Precificação!F:F) -> 5316 | J27: 78626.8 | L27: Marítimo | M27: 0 | N27: 0 | O27: 0 | P27: 0 | Q27: 1537.1 | R27: 1300 | S27: 0 | T27: 0 | U27: =SUM(M27:T27) -> 2837.1 | W27: CHINA | X27: =IF(K27<>"", "CONCLUÍDO", IF(E27<>"", "EM TRÂNSITO", "EM PRODUÇÃO")) -> EM TRÂNSITO | Y27: =Tabela2[[#This Row],[ESTIMATIVA CHEGADA]]-TODAY() -> 1 | Z27: 46242
A28: =A27+1 -> 27 | B28: TIMBRO SWISS SA | C28: 4508577003 | D28: BEMOL 39 | G28: =COUNTIF(Precificação!A:A,'Base de Dados'!D38) -> 9 | H28: BATEDEIRAS | I28: =SUMIF(Precificação!A:A,D28,Precificação!F:F) -> 1760 | J28: 56320 | L28: Marítimo | M28: 0 | N28: 0 | O28: 0 | P28: 0 | Q28: 1537.1 | R28: 1300 | S28: 0 | T28: 0 | U28: =SUM(M28:T28) -> 2837.1 | W28: CHINA | X28: =IF(K28<>"", "CONCLUÍDO", IF(E28<>"", "EM TRÂNSITO", "EM PRODUÇÃO")) -> EM PRODUÇÃO | Y28: =Tabela2[[#This Row],[ESTIMATIVA CHEGADA]]-TODAY() -> 84 | Z28: =Tabela2[[#This Row],[PRONTIDÃO]]+60 -> 46325 | AA28: 46265
A29: =A28+1 -> 28 | B29: TIMBRO SWISS SA | C29: 4508559921 | D29: BEMOL 40 | E29: CAN31113002 | F29: HLBU2443445/ UACU5972213/ HAMU1170011 | G29: =COUNTIF(Precificação!A:A,'Base de Dados'!D21) -> 6 | H29: FORNO 60L | I29: =SUMIF(Precificação!A:A,D29,Precificação!F:F) -> 1575 | J29: 64118.25 | K29: 2026000211 | L29: Marítimo | M29: 327567.32 | N29: 44344.38 | O29: 219.73 | P29: 154.23 | Q29: 1537.1 | R29: 1300 | S29: 35910.68 | T29: 7814.76 | U29: =SUM(M29:T29) -> 418848.2 | V29: =N29/M29 -> 0.13537486 | W29: CHINA | X29: =IF(K29<>"", "CONCLUÍDO", IF(E29<>"", "EM TRÂNSITO", "EM PRODUÇÃO")) -> CONCLUÍDO | Z29: 46159
A30: =A29+1 -> 29 | B30: TIMBRO SWISS SA | C30: Criar Ordem | D30: BEMOL 41 | G30: =COUNTIF(Precificação!A:A,'Base de Dados'!D32) -> 1 | H30: CAFETEIRAEMIXER | I30: =SUMIF(Precificação!A:A,D30,Precificação!F:F) -> 0 | J30: 48031.6 | L30: Marítimo | M30: 0 | N30: 0 | O30: 0 | P30: 0 | Q30: 1537.1 | R30: 1300 | S30: 0 | T30: 0 | U30: =SUM(M30:T30) -> 2837.1 | W30: CHINA | X30: =IF(K30<>"", "CONCLUÍDO", IF(E30<>"", "EM TRÂNSITO", "EM PRODUÇÃO")) -> EM PRODUÇÃO | Y30: =Tabela2[[#This Row],[ESTIMATIVA CHEGADA]]-TODAY() -> 66 | Z30: =Tabela2[[#This Row],[PRONTIDÃO]]+60 -> 46307 | AA30: 46247
A31: =A30+1 -> 30 | B31: TIMBRO SWISS SA | C31: 4508751681 | D31: BEMOL 42 | E31: SHA31178711 | F31: FANU1271087/ HAMU1390865/ HLXU8347322 | G31: =COUNTIF(Precificação!A:A,'Base de Dados'!D20) -> 9 | H31: POTES VDR COM TAMPA | I31: =SUMIF(Precificação!A:A,D31,Precificação!F:F) -> 34966 | J31: 87103.88 | K31: 2026000202 | L31: Marítimo | M31: 450475.1 | N31: 47171.08 | O31: 293.6 | P31: 154.23 | Q31: 1537.1 | R31: 1300 | S31: 48051.19 | T31: 10456.74 | U31: =SUM(M31:T31) -> 559439.04 | V31: =N31/M31 -> 0.10471407 | W31: CHINA | X31: =IF(K31<>"", "CONCLUÍDO", IF(E31<>"", "EM TRÂNSITO", "EM PRODUÇÃO")) -> CONCLUÍDO | Z31: 46156
A32: =A31+1 -> 31 | B32: TIMBRO SWISS SA | C32: 4508840505 | D32: BEMOL 43 | G32: =COUNTIF(Precificação!A:A,'Base de Dados'!D34) -> 18 | H32: SECADOR DE CABELO | CONCLUSÃO EM JULHO | I32: =SUMIF(Precificação!A:A,D32,Precificação!F:F) -> 2004 | J32: 46552.92 | L32: Marítimo | M32: 0 | N32: 0 | O32: 0 | P32: 0 | Q32: 1537.1 | R32: 1300 | S32: 0 | T32: 0 | U32: =SUM(M32:T32) -> 2837.1 | W32: CHINA | X32: =IF(K32<>"", "CONCLUÍDO", IF(E32<>"", "EM TRÂNSITO", "EM PRODUÇÃO")) -> EM PRODUÇÃO | Y32: =Tabela2[[#This Row],[ESTIMATIVA CHEGADA]]-TODAY() -> 68 | Z32: =Tabela2[[#This Row],[PRONTIDÃO]]+60 -> 46309 | AA32: 46249
A33: =A32+1 -> 32 | B33: TIMBRO SWISS SA | C33: 4508894878 | D33: BEMOL 45 | E33: 1074377332 | F33: FSCU8231725 | G33: =COUNTIF(Precificação!A:A,'Base de Dados'!D43) -> 1 | H33: LIQUIDIFICADOR, MÁQUINA, SUPORTE E VAPORIZADOR | I33: =SUMIF(Precificação!A:A,D33,Precificação!F:F) -> 5324 | J33: 89848.96 | K33: 2026000235 | L33: Marítimo | M33: 0 | N33: 0 | O33: 0 | P33: 0 | Q33: 1537.1 | R33: 1300 | S33: 0 | T33: 0 | U33: =SUM(M33:T33) -> 2837.1 | W33: CHINA | X33: =IF(K33<>"", "CONCLUÍDO", IF(E33<>"", "EM TRÂNSITO", "EM PRODUÇÃO")) -> CONCLUÍDO | Z33: 46233
A34: =A33+1 -> 33 | B34: TIMBRO SWISS SA | C34: 4508897867 | D34: BEMOL 46 | E34: SHAS010316 | G34: =COUNTIF(Precificação!A:A,'Base de Dados'!D44) -> 7 | H34: EDREDOM | I34: =SUMIF(Precificação!A:A,D34,Precificação!F:F) -> 8112 | J34: 163113.6 | L34: Marítimo | M34: 0 | N34: 0 | O34: 0 | P34: 0 | Q34: 1537.1 | R34: 1300 | S34: 0 | T34: 0 | U34: =SUM(M34:T34) -> 2837.1 | X34: =IF(K34<>"", "CONCLUÍDO", IF(E34<>"", "EM TRÂNSITO", "EM PRODUÇÃO")) -> EM TRÂNSITO | Y34: =Tabela2[[#This Row],[ESTIMATIVA CHEGADA]]-TODAY() -> 53 | Z34: 46294
A35: =A34+1 -> 34 | B35: TIMBRO SWISS SA | C35: 4508840296 | D35: BEMOL 47 | E35: CAN31113229 | F35: HAMU1899636 | G35: =COUNTIF(Precificação!A:A,'Base de Dados'!D33) -> 4 | H35: FORNO ELETRICO | I35: =SUMIF(Precificação!A:A,D35,Precificação!F:F) -> 500 | J35: 20355 | K35: 2026000234 | L35: Marítimo | M35: 0 | N35: 0 | O35: 0 | P35: 0 | Q35: 1537.1 | R35: 1300 | S35: 0 | T35: 0 | U35: =SUM(M35:T35) -> 2837.1 | W35: CHINA | X35: =IF(K35<>"", "CONCLUÍDO", IF(E35<>"", "EM TRÂNSITO", "EM PRODUÇÃO")) -> CONCLUÍDO | Z35: 46233
A36: =A35+1 -> 35 | B36: TIMBRO SWISS SA | C36: 4508840510 | D36: BEMOL 48 | E36: NGB31167475 | F36: GAOU7397863 | G36: =COUNTIF(Precificação!A:A,'Base de Dados'!D35) -> 1 | H36: AIRFRYER 12L | I36: =SUMIF(Precificação!A:A,D36,Precificação!F:F) -> 1112 | J36: 42044.72 | K36: 2026000228 | L36: Marítimo | M36: 0 | N36: 0 | O36: 0 | P36: 0 | Q36: 1537.1 | R36: 1300 | S36: 0 | T36: 0 | U36: =SUM(M36:T36) -> 2837.1 | W36: CHINA | X36: =IF(K36<>"", "CONCLUÍDO", IF(E36<>"", "EM TRÂNSITO", "EM PRODUÇÃO")) -> CONCLUÍDO | Z36: 46231
A37: =A36+1 -> 36 | B37: TIMBRO SWISS SA | C37: 4508840536 | D37: BEMOL 49 | E37: NGB31168106 | F37: MSBU5188110 | G37: =COUNTIF(Precificação!A:A,'Base de Dados'!D36) -> 1 | H37: GRILL, ESCOVA SECADORA, CHAPINHA, SANDUICHEIRA E ESPREMEDOR DE FRUTAS | I37: =SUMIF(Precificação!A:A,D37,Precificação!F:F) -> 10044 | J37: 14886 | K37: 2026000238 | L37: Marítimo | M37: 0 | N37: 0 | O37: 0 | P37: 0 | Q37: 1537.1 | R37: 1300 | S37: 0 | T37: 0 | U37: =SUM(M37:T37) -> 2837.1 | W37: CHINA | X37: =IF(K37<>"", "CONCLUÍDO", IF(E37<>"", "EM TRÂNSITO", "EM PRODUÇÃO")) -> CONCLUÍDO | Z37: 46238
A38: =A37+1 -> 37 | B38: TIMBRO SWISS SA | C38: 4508840545 | D38: BEMOL 50 | E38: NGBS000622 | F38: FANU3565630/ HLBU1619885 | G38: =COUNTIF(Precificação!A:A,'Base de Dados'!D37) -> 5 | H38: BEAUTY CHUMBO + AIR FRYER+ TRAVESSAS | I38: =SUMIF(Precificação!A:A,D38,Precificação!F:F) -> 15694 | J38: 125124.1 | L38: Marítimo | M38: 0 | N38: 0 | O38: 0 | P38: 0 | Q38: 1537.1 | R38: 1300 | S38: 0 | T38: 0 | U38: =SUM(M38:T38) -> 2837.1 | W38: CHINA | X38: =IF(K38<>"", "CONCLUÍDO", IF(E38<>"", "EM TRÂNSITO", "EM PRODUÇÃO")) -> EM TRÂNSITO | Y38: =Tabela2[[#This Row],[ESTIMATIVA CHEGADA]]-TODAY() -> 26 | Z38: 46267
A39: =A38+1 -> 38 | B39: TIMBRO SWISS SA | C39: 4508699466 | D39: BEMOL 51 | E39: SHAS003420 | F39: MSNU9335746 | G39: =COUNTIF(Precificação!A:A,'Base de Dados'!D39) -> 4 | H39: POTES DE VIDROS | I39: =SUMIF(Precificação!A:A,D39,Precificação!F:F) -> 11244 | J39: 30226.2 | L39: Marítimo | M39: 0 | N39: 0 | O39: 0 | P39: 0 | Q39: 1537.1 | R39: 1300 | S39: 0 | T39: 0 | U39: =SUM(M39:T39) -> 2837.1 | W39: CHINA | X39: =IF(K39<>"", "CONCLUÍDO", IF(E39<>"", "EM TRÂNSITO", "EM PRODUÇÃO")) -> EM TRÂNSITO | Y39: =Tabela2[[#This Row],[ESTIMATIVA CHEGADA]]-TODAY() -> 32 | Z39: 46273
A40: =A39+1 -> 39 | B40: TIMBRO SWISS SA | C40: 4508894889 | D40: BEMOL 52 | F40: SEM CTN | G40: =COUNTIF(Precificação!A:A,'Base de Dados'!D45) -> 2 | H40: COPO LIQUIDIFICADOR GSE019 | I40: =SUMIF(Precificação!A:A,D40,Precificação!F:F) -> 992 | J40: 1517.76 | L40: Aéreo | M40: 0 | N40: 0 | O40: 0 | P40: 0 | Q40: 1537.1 | R40: 1300 | S40: 0 | T40: 0 | U40: =SUM(M40:T40) -> 2837.1 | X40: =IF(K40<>"", "CONCLUÍDO", IF(E40<>"", "EM TRÂNSITO", "EM PRODUÇÃO")) -> EM PRODUÇÃO | Z40: 46238
...

Sheet Precificação
A1: INVOICE | B1: Fornecedor | C1: Status | D1: Cód | E1: Descrição | F1: Qtd | G1: Custo individual UDS | H1: Taxa dolar DI | I1: Custo individual BRL | J1: Custo Total | K1: % Participação | L1: Frete BRL | M1: Custo total + Frete BRL | N1: Custo individual com frete BRL | O1: MARK UP | P1: Preço de venda | Q1: Margem | R1: MARK UP CATEGORIA | S1: Ganho de Margem | T1: Preço produto similar | U1: Dif de preço | V1: GM9 | W1: DESCRIÇÃO GM9
A2: BEMOL 34 | B2: =_xlfn.XLOOKUP(A2,'Base de Dados'!D:D,'Base de Dados'!B:B) -> TIMBRO SWISS SA | C2: =_xlfn.XLOOKUP(PRECIFICAÇÃO[[#This Row],[INVOICE]],'Base de Dados'!D:D,'Base de Dados'!X:X) -> CONCLUÍDO | D2: 267869 | E2: POTE BAUMON HERMÉT 400ML RET C/T R145 | F2: 2052 | G2: 0.74 | H2: 5.0378 | I2: =H2*G2 -> 3.727972 | J2: =I2*F2 -> 7649.7985 | K2: =J2/_xlfn.XLOOKUP(A2,'Base de Dados'!D:D,'Base de Dados'!M:M) -> 0.023351344 | L2: =K2*_xlfn.XLOOKUP(A2,'Base de Dados'!D:D,'Base de Dados'!N:N) -> 635.25277 | M2: =J2+L2 -> 8285.0513 | N2: =M2/F2 -> 4.0375494 | O2: =R2-0.1 -> 0.4092054 | P2: =ROUND(N2/O2,0) -> 10 | Q2: =(P2-N2)/P2 -> 0.59624506 | R2: 0.5092054 | S2: =Q2-R2 -> 0.087039663 | T2: =P2+10 -> 20 | U2: =(T2-P2)/T2 -> 0.5 | V2: 127001014 | W2: POTES
A3: BEMOL 34 | B3: =_xlfn.XLOOKUP(A3,'Base de Dados'!D:D,'Base de Dados'!B:B) -> TIMBRO SWISS SA | C3: =_xlfn.XLOOKUP(PRECIFICAÇÃO[[#This Row],[INVOICE]],'Base de Dados'!D:D,'Base de Dados'!X:X) -> CONCLUÍDO | D3: 267937 | E3: POTE BAUMON HERMÉT 1020ML RET C/T S195-3 | F3: 744 | G3: 1.79 | H3: 5.0378 | I3: =H3*G3 -> 9.017662 | J3: =I3*F3 -> 6709.1405 | K3: =J3/_xlfn.XLOOKUP(A3,'Base de Dados'!D:D,'Base de Dados'!M:M) -> 0.020479945 | L3: =K3*_xlfn.XLOOKUP(A3,'Base de Dados'!D:D,'Base de Dados'!N:N) -> 557.13887 | M3: =J3+L3 -> 7266.2794 | N3: =M3/F3 -> 9.7665046 | O3: =R3-0.1 -> 0.4092054 | P3: =ROUND(N3/O3,0) -> 24 | Q3: =(P3-N3)/P3 -> 0.59306231 | R3: 0.5092054 | S3: =Q3-R3 -> 0.08385691 | T3: =P3+10 -> 34 | U3: =(T3-P3)/T3 -> 0.29411765 | V3: 127001014 | W3: POTES
A4: BEMOL 34 | B4: =_xlfn.XLOOKUP(A4,'Base de Dados'!D:D,'Base de Dados'!B:B) -> TIMBRO SWISS SA | C4: =_xlfn.XLOOKUP(PRECIFICAÇÃO[[#This Row],[INVOICE]],'Base de Dados'!D:D,'Base de Dados'!X:X) -> CONCLUÍDO | D4: 267941 | E4: ASSAD BAUMON QUAD 1800ML VDR GB-S1800 | F4: 2496 | G4: 1.53 | H4: 5.0378 | I4: =H4*G4 -> 7.707834 | J4: =I4*F4 -> 19238.754 | K4: =J4/_xlfn.XLOOKUP(A4,'Base de Dados'!D:D,'Base de Dados'!M:M) -> 0.058727136 | L4: =K4*_xlfn.XLOOKUP(A4,'Base de Dados'!D:D,'Base de Dados'!N:N) -> 1597.6201 | M4: =J4+L4 -> 20836.374 | N4: =M4/F4 -> 8.3479061 | O4: =R4-0.1 -> 0.42527551 | P4: =ROUND(N4/O4,0) -> 20 | Q4: =(P4-N4)/P4 -> 0.58260469 | R4: 0.52527551 | S4: =Q4-R4 -> 0.057329181 | T4: =P4+10 -> 30 | U4: =(T4-P4)/T4 -> 0.33333333 | V4: 127001002 | W4: ASSADEIRAS/FÔRMAS
A5: BEMOL 34 | B5: =_xlfn.XLOOKUP(A5,'Base de Dados'!D:D,'Base de Dados'!B:B) -> TIMBRO SWISS SA | C5: =_xlfn.XLOOKUP(PRECIFICAÇÃO[[#This Row],[INVOICE]],'Base de Dados'!D:D,'Base de Dados'!X:X) -> CONCLUÍDO | D5: 267942 | E5: CAÇAROLA BAUMON 1000ML VIDRO GC-1000 | F5: 2496 | G5: 1.46 | H5: 5.0378 | I5: =H5*G5 -> 7.355188 | J5: =I5*F5 -> 18358.549 | K5: =J5/_xlfn.XLOOKUP(A5,'Base de Dados'!D:D,'Base de Dados'!M:M) -> 0.056040273 | L5: =K5*_xlfn.XLOOKUP(A5,'Base de Dados'!D:D,'Base de Dados'!N:N) -> 1524.5263 | M5: =J5+L5 -> 19883.076 | N5: =M5/F5 -> 7.9659758 | O5: =R5-0.1 -> 0.44079732 | P5: =ROUND(N5/O5,0) -> 18 | Q5: =(P5-N5)/P5 -> 0.55744579 | R5: 0.54079732 | S5: =Q5-R5 -> 0.01664847 | T5: =P5+10 -> 28 | U5: =(T5-P5)/T5 -> 0.35714286 | V5: 127001006 | W5: CAÇAROLA
A6: BEMOL 34 | B6: =_xlfn.XLOOKUP(A6,'Base de Dados'!D:D,'Base de Dados'!B:B) -> TIMBRO SWISS SA | C6: =_xlfn.XLOOKUP(PRECIFICAÇÃO[[#This Row],[INVOICE]],'Base de Dados'!D:D,'Base de Dados'!X:X) -> CONCLUÍDO | D6: 267945 | E6: ASSADEIRA BAUMON 1800ML VDR GC-O1800 | F6: 7800 | G6: 3.01 | H6: 5.0378 | I6: =H6*G6 -> 15.163778 | J6: =I6*F6 -> 118277.47 | K6: =J6/_xlfn.XLOOKUP(A6,'Base de Dados'!D:D,'Base de Dados'!M:M) -> 0.36104714 | L6: =K6*_xlfn.XLOOKUP(A6,'Base de Dados'!D:D,'Base de Dados'!N:N) -> 9821.9697 | M6: =J6+L6 -> 128099.44 | N6: =M6/F6 -> 16.423005 | O6: =R6-0.1 -> 0.42527551 | P6: =ROUND(N6/O6,0) -> 39 | Q6: =(P6-N6)/P6 -> 0.57889731 | R6: 0.52527551 | S6: =Q6-R6 -> 0.053621799 | T6: =P6+10 -> 49 | U6: =(T6-P6)/T6 -> 0.20408163 | V6: 127001002 | W6: ASSADEIRAS/FÔRMAS
A7: BEMOL 34 | B7: =_xlfn.XLOOKUP(A7,'Base de Dados'!D:D,'Base de Dados'!B:B) -> TIMBRO SWISS SA | C7: =_xlfn.XLOOKUP(PRECIFICAÇÃO[[#This Row],[INVOICE]],'Base de Dados'!D:D,'Base de Dados'!X:X) -> CONCLUÍDO | D7: 268132 | E7: POTE BAUMON HERMÉT 2260ML RET C/T JL002 | F7: 12984 | G7: 2.11 | H7: 5.0378 | I7: =H7*G7 -> 10.629758 | J7: =I7*F7 -> 138016.78 | K7: =J7/_xlfn.XLOOKUP(A7,'Base de Dados'!D:D,'Base de Dados'!M:M) -> 0.42130224 | L7: =K7*_xlfn.XLOOKUP(A7,'Base de Dados'!D:D,'Base de Dados'!N:N) -> 11461.157 | M7: =J7+L7 -> 149477.93 | N7: =M7/F7 -> 11.512472 | O7: =R7-0.1 -> 0.4092054 | P7: =ROUND(N7/O7,0) -> 28 | Q7: =(P7-N7)/P7 -> 0.58884029 | R7: 0.5092054 | S7: =Q7-R7 -> 0.079634891 | T7: =P7+10 -> 38 | U7: =(T7-P7)/T7 -> 0.26315789 | V7: 127001014 | W7: POTES
A8: BEMOL 34 | B8: =_xlfn.XLOOKUP(A8,'Base de Dados'!D:D,'Base de Dados'!B:B) -> TIMBRO SWISS SA | C8: =_xlfn.XLOOKUP(PRECIFICAÇÃO[[#This Row],[INVOICE]],'Base de Dados'!D:D,'Base de Dados'!X:X) -> CONCLUÍDO | D8: 268133 | E8: POTE BAUMON HERMÉT 1040ML C/T R195 | F8: 3000 | G8: 1.28 | H8: 5.0378 | I8: =H8*G8 -> 6.448384 | J8: =I8*F8 -> 19345.152 | K8: =J8/_xlfn.XLOOKUP(A8,'Base de Dados'!D:D,'Base de Dados'!M:M) -> 0.059051921 | L8: =K8*_xlfn.XLOOKUP(A8,'Base de Dados'!D:D,'Base de Dados'!N:N) -> 1606.4556 | M8: =J8+L8 -> 20951.608 | N8: =M8/F8 -> 6.9838692 | O8: =R8-0.1 -> 0.4092054 | P8: =ROUND(N8/O8,0) -> 17 | Q8: =(P8-N8)/P8 -> 0.58918417 | R8: 0.5092054 | S8: =Q8-R8 -> 0.079978766 | T8: =P8+10 -> 27 | U8: =(T8-P8)/T8 -> 0.37037037 | V8: 127001014 | W8: POTES
